Workbook

Sheet Lubes SKU level summary
B1: Category | C1: Lubes
A2: Values copy of the pivot in Talabat_Durex_cleaned_Analysis.xlsx (same cell positions), so the Deep Dive formulas resolve. | BI2: ASP
C3: Column Labels
C4: Sum of Ordered Revenue | U4: Sum of Ordered Units | AM4: Distinct Count of ASIN | BE4: Total Sum of Ordered Revenue | BF4: Total Sum of Ordered Units | BG4: Total Distinct Count of ASIN
C5: 2025 | O5: 2025 Total | P5: 2026 | T5: 2026 Total | U5: 2025 | AG5: 2025 Total | AH5: 2026 | AL5: 2026 Total | AM5: 2025 | AY5: 2025 Total | AZ5: 2026 | BD5: 2026 Total | BI5: 2025 | BU5: 2025 Total | BV5: 2026 | BZ5: 2026 Total
A6: Remarks | B6: Row Labels | C6: January | D6: February | E6: March | F6: April | G6: May | H6: June | I6: July | J6: August | K6: September | L6: October | M6: November | N6: December | P6: January | Q6: February | R6: March | S6: April | U6: January | V6: February | W6: March | X6: April | Y6: May | Z6: June | AA6: July | AB6: August | AC6: September | AD6: October | AE6: November | AF6: December | AH6: January | AI6: February | AJ6: March | AK6: April | AM6: January | AN6: February | AO6: March | AP6: April | AQ6: May | AR6: June | AS6: July | AT6: August | AU6: September | AV6: October | AW6: November | AX6: December | AZ6: January | BA6: February | BB6: March | BC6: April | BH6: Live month | BI6: January | BJ6: February | BK6: March | BL6: April | BM6: May | BN6: June | BO6: July | BP6: August | BQ6: September | BR6: October | BS6: November | BT6: December | BV6: January | BW6: February | BX6: March | BY6: April
B7: 50 ml | C7: 436965.22 | D7: 438280.35 | E7: 358256.64 | F7: 461806.81 | G7: 519755.4 | H7: 528365.1 | I7: 542787.9 | J7: 549120.6 | K7: 531814.88 | L7: 566653.2 | M7: 536543.07 | N7: 513170.55 | O7: 5983519.7 | P7: 555408.15 | Q7: 469128.3 | R7: 486611.85 | S7: 529229.55 | T7: 2040377.9 | U7: 1637 | V7: 1598 | W7: 1305 | X7: 1719 | Y7: 1959 | Z7: 2083 | AA7: 2114 | AB7: 2135 | AC7: 1942 | AD7: 1996 | AE7: 2092 | AF7: 2010 | AG7: 22590 | AH7: 2152 | AI7: 1845 | AJ7: 1903 | AK7: 2050 | AL7: 7950 | AM7: 4 | AN7: 4 | AO7: 4 | AP7: 4 | AQ7: 4 | AR7: 4 | AS7: 4 | AT7: 4 | AU7: 4 | AV7: 4 | AW7: 4 | AX7: 4 | AY7: 4 | AZ7: 4 | BA7: 4 | BB7: 4 | BC7: 4 | BD7: 4 | BE7: 8023897.6 | BF7: 30540 | BG7: 4 | BI7: 266.9305 | BJ7: 274.26805 | BK7: 274.52616 | BL7: 268.64852 | BM7: 265.31669 | BN7: 253.65583 | BO7: 256.7587 | BP7: 257.19934 | BQ7: 273.84906 | BR7: 283.89439 | BS7: 256.47374 | BT7: 255.30873 | BU7: 264.87471 | BV7: 258.08929 | BW7: 254.27008 | BX7: 255.70775 | BY7: 258.16076 | BZ7: 256.6513
B8: Durex Play Cheeky Cherry Lube Gel, 50ml | C8: 163893.52 | D8: 190113.82 | E8: 147475.21 | F8: 183417.36 | G8: 192663.08 | H8: 222321.52 | I8: 215518.35 | J8: 221302.5 | K8: 202765.12 | L8: 214731.75 | M8: 206600.57 | N8: 199010.55 | O8: 2359813.4 | P8: 216340.58 | Q8: 185002.58 | R8: 188382.52 | S8: 220476.9 | T8: 810202.57 | U8: 601 | V8: 700 | W8: 543 | X8: 680 | Y8: 721 | Z8: 893 | AA8: 854 | AB8: 874 | AC8: 698 | AD8: 732 | AE8: 804 | AF8: 785 | AG8: 8885 | AH8: 860 | AI8: 742 | AJ8: 759 | AK8: 873 | AL8: 3234 | AM8: 1 | AN8: 1 | AO8: 1 | AP8: 1 | AQ8: 1 | AR8: 1 | AS8: 1 | AT8: 1 | AU8: 1 | AV8: 1 | AW8: 1 | AX8: 1 | AY8: 1 | AZ8: 1 | BA8: 1 | BB8: 1 | BC8: 1 | BD8: 1 | BE8: 3170015.9 | BF8: 12119 | BG8: 1 | BH8: 16 | BI8: 272.70137 | BJ8: 271.59118 | BK8: 271.5934 | BL8: 269.73141 | BM8: 267.21647 | BN8: 248.96027 | BO8: 252.36341 | BP8: 253.20652 | BQ8: 290.49445 | BR8: 293.34939 | BS8: 256.96588 | BT8: 253.51662 | BU8: 265.5952 | BV8: 251.55881 | BW8: 249.32962 | BX8: 248.19832 | BY8: 252.55086 | BZ8: 250.52646
B9: Durex Play Feel Lube Gel, 50ml | C9: 131352.9 | D9: 107639.4 | E9: 91599.286 | F9: 124604.62 | G9: 151203.83 | H9: 115146.9 | I9: 145286.48 | J9: 157325.7 | K9: 190778.33 | L9: 208837.42 | M9: 170029.21 | N9: 169161.15 | O9: 1762965.2 | P9: 178601.03 | Q9: 152177.48 | R9: 165305.55 | S9: 170192.33 | T9: 666276.38 | U9: 532 | V9: 394 | W9: 335 | X9: 481 | Y9: 603 | Z9: 466 | AA9: 579 | AB9: 624 | AC9: 757 | AD9: 785 | AE9: 689 | AF9: 695 | AG9: 6940 | AH9: 721 | AI9: 628 | AJ9: 675 | AK9: 691 | AL9: 2715 | AM9: 1 | AN9: 1 | AO9: 1 | AP9: 1 | AQ9: 1 | AR9: 1 | AS9: 1 | AT9: 1 | AU9: 1 | AV9: 1 | AW9: 1 | AX9: 1 | AY9: 1 | AZ9: 1 | BA9: 1 | BB9: 1 | BC9: 1 | BD9: 1 | BE9: 2429241.6 | BF9: 9655 | BG9: 1 | BH9: 16 | BI9: 246.90395 | BJ9: 273.19645 | BK9: 273.4307 | BL9: 259.05327 | BM9: 250.75261 | BN9: 247.09635 | BO9: 250.92655 | BP9: 252.12452 | BQ9: 252.01892 | BR9: 266.03494 | BS9: 246.7768 | BT9: 243.39734 | BU9: 254.02957 | BV9: 247.71293 | BW9: 242.32082 | BX9: 244.89711 | BY9: 246.29859 | BZ9: 245.40566
B10: Durex Play Tingle Lube Gel, 50ml | C10: 66135.525 | D10: 71254.65 | E10: 59774.143 | F10: 73551.082 | G10: 84851.625 | H10: 93442.875 | I10: 89486.325 | J10: 83103.15 | K10: 65842.2 | L10: 68184.375 | M10: 80699.071 | N10: 83893.95 | O10: 920218.97 | P10: 85635.075 | Q10: 75416.1 | R10: 67242 | S10: 69610.725 | T10: 297903.9 | U10: 243 | V10: 262 | W10: 220 | X10: 274 | Y10: 317 | Z10: 374 | AA10: 357 | AB10: 332 | AC10: 246 | AD10: 243 | AE10: 321 | AF10: 335 | AG10: 3524 | AH10: 342 | AI10: 302 | AJ10: 268 | AK10: 275 | AL10: 1187 | AM10: 1 | AN10: 1 | AO10: 1 | AP10: 1 | AQ10: 1 | AR10: 1 | AS10: 1 | AT10: 1 | AU10: 1 | AV10: 1 | AW10: 1 | AX10: 1 | AY10: 1 | AZ10: 1 | BA10: 1 | BB10: 1 | BC10: 1 | BD10: 1 | BE10: 1218122.9 | BF10: 4711 | BG10: 1 | BH10: 16 | BI10: 272.16265 | BJ10: 271.96431 | BK10: 271.70065 | BL10: 268.43461 | BM10: 267.67074 | BN10: 249.84726 | BO10: 250.66197 | BP10: 250.31069 | BQ10: 267.65122 | BR10: 280.59414 | BS10: 251.39898 | BT10: 250.4297 | BU10: 261.12911 | BV10: 250.39496 | BW10: 249.72219 | BX10: 250.90299 | BY10: 253.12991 | BZ10: 250.97211
B11: Durex Maxima Lubricant Gel, 50ml | C11: 75583.275 | D11: 69272.475 | E11: 59408 | F11: 80233.746 | G11: 91036.875 | H11: 97453.8 | I11: 92496.75 | J11: 87389.25 | K11: 72429.225 | L11: 74899.65 | M11: 79214.214 | N11: 61104.9 | O11: 940522.16 | P11: 74831.475 | Q11: 56532.15 | R11: 65681.775 | S11: 68949.6 | T11: 265995 | U11: 261 | V11: 242 | W11: 207 | X11: 284 | Y11: 318 | Z11: 350 | AA11: 324 | AB11: 305 | AC11: 241 | AD11: 236 | AE11: 278 | AF11: 195 | AG11: 3241 | AH11: 229 | AI11: 173 | AJ11: 201 | AK11: 211 | AL11: 814 | AM11: 1 | AN11: 1 | AO11: 1 | AP11: 1 | AQ11: 1 | AR11: 1 | AS11: 1 | AT11: 1 | AU11: 1 | AV11: 1 | AW11: 1 | AX11: 1 | AY11: 1 | AZ11: 1 | BA11: 1 | BB11: 1 | BC11: 1 | BD11: 1 | BE11: 1206517.2 | BF11: 4055 | BG11: 1 | BH11: 16 | BI11: 289.59109 | BJ11: 286.2499 | BK11: 286.99517 | BL11: 282.51319 | BM11: 286.27948 | BN11: 278.43943 | BO11: 285.4838 | BP11: 286.52213 | BQ11: 300.5362 | BR11: 317.3714 | BS11: 284.94322 | BT11: 313.35846 | BU11: 290.19505 | BV11: 326.775 | BW11: 326.77543 | BX11: 326.775 | BY11: 326.77536 | BZ11: 326.77518
B12: 200 ml | C12: 72232.95 | D12: 103038.82 | E12: 86856.571 | F12: 124507.99 | G12: 125493.23 | H12: 139249.2 | I12: 119585.02 | J12: 146843.55 | K12: 132972.6 | L12: 143710.95 | M12: 151327 | N12: 159948.15 | O12: 1505766 | P12: 138956.33 | Q12: 124647.68 | R12: 126231.45 | S12: 122746.65 | T12: 512582.1 | U12: 123 | V12: 171 | W12: 143 | X12: 211 | Y12: 209 | Z12: 243 | AA12: 209 | AB12: 256 | AC12: 222 | AD12: 231 | AE12: 266 | AF12: 282 | AG12: 2566 | AH12: 242 | AI12: 218 | AJ12: 223 | AK12: 213 | AL12: 896 | AM12: 2 | AN12: 2 | AO12: 2 | AP12: 2 | AQ12: 2 | AR12: 2 | AS12: 2 | AT12: 2 | AU12: 2 | AV12: 2 | AW12: 2 | AX12: 2 | AY12: 2 | AZ12: 2 | BA12: 2 | BB12: 2 | BC12: 2 | BD12: 2 | BE12: 2018348.1 | BF12: 3462 | BG12: 2 | BI12: 587.25976 | BJ12: 602.56623 | BK12: 607.38861 | BL12: 590.08527 | BM12: 600.44605 | BN12: 573.04198 | BO12: 572.17715 | BP12: 573.60762 | BQ12: 598.97568 | BR12: 622.12532 | BS12: 568.8985 | BT12: 567.19202 | BU12: 586.81451 | BV12: 574.19969 | BW12: 571.77833 | BX12: 566.06031 | BY12: 576.27535 | BZ12: 572.07824
B13: Durex Play Massage 2-in-1 Lube Soothing Aloe Vera Gel, 200ml | C13: 56886.375 | D13: 47716.125 | E13: 53390.857 | F13: 68904.064 | G13: 67924.275 | H13: 80845.125 | I13: 76118.7 | J13: 78620.175 | K13: 70155.525 | L13: 77440.275 | M13: 90358.429 | N13: 86432.625 | O13: 854792.55 | P13: 87299.25 | Q13: 66846.075 | R13: 63814.725 | S13: 67394.475 | T13: 285354.53 | U13: 97 | V13: 80 | W13: 88 | X13: 117 | Y13: 113 | Z13: 141 | AA13: 133 | AB13: 137 | AC13: 117 | AD13: 125 | AE13: 159 | AF13: 153 | AG13: 1460 | AH13: 152 | AI13: 117 | AJ13: 111 | AK13: 117 | AL13: 497 | AM13: 1 | AN13: 1 | AO13: 1 | AP13: 1 | AQ13: 1 | AR13: 1 | AS13: 1 | AT13: 1 | AU13: 1 | AV13: 1 | AW13: 1 | AX13: 1 | AY13: 1 | AZ13: 1 | BA13: 1 | BB13: 1 | BC13: 1 | BD13: 1 | BE13: 1140147.1 | BF13: 1957 | BG13: 1 | BH13: 16 | BI13: 586.45747 | BJ13: 596.45156 | BK13: 606.71429 | BL13: 588.92363 | BM13: 601.09978 | BN13: 573.36968 | BO13: 572.32105 | BP13: 573.86989 | BQ13: 599.61987 | BR13: 619.5222 | BS13: 568.292 | BT13: 564.91912 | BU13: 585.47435 | BV13: 574.33717 | BW13: 571.33397 | BX13: 574.90743 | BY13: 576.02115 | BZ13: 574.15397
B14: Durex Play Sensual Massage 2-in-1 Lube with Ylang Ylang Gel, 200ml | C14: 15346.575 | D14: 55322.7 | E14: 33465.714 | F14: 55603.929 | G14: 57568.95 | H14: 58404.075 | I14: 43466.325 | J14: 68223.375 | K14: 62817.075 | L14: 66270.675 | M14: 60968.571 | N14: 73515.525 | O14: 650973.49 | P14: 51657.075 | Q14: 57801.6 | R14: 62416.725 | S14: 55352.175 | T14: 227227.58 | U14: 26 | V14: 91 | W14: 55 | X14: 94 | Y14: 96 | Z14: 102 | AA14: 76 | AB14: 119 | AC14: 105 | AD14: 106 | AE14: 107 | AF14: 129 | AG14: 1106 | AH14: 90 | AI14: 101 | AJ14: 112 | AK14: 96 | AL14: 399 | AM14: 1 | AN14: 1 | AO14: 1 | AP14: 1 | AQ14: 1 | AR14: 1 | AS14: 1 | AT14: 1 | AU14: 1 | AV14: 1 | AW14: 1 | AX14: 1 | AY14: 1 | AZ14: 1 | BA14: 1 | BB14: 1 | BC14: 1 | BD14: 1 | BE14: 878201.06 | BF14: 1505 | BG14: 1 | BH14: 16 | BI14: 590.25288 | BJ14: 607.94176 | BK14: 608.46753 | BL14: 591.53116 | BM14: 599.67656 | BN14: 572.58897 | BO14: 571.92533 | BP14: 573.30567 | BQ14: 598.25786 | BR14: 625.19505 | BS14: 569.79973 | BT14: 569.88779 | BU14: 588.58363 | BV14: 573.9675 | BW14: 572.29307 | BX14: 557.29219 | BY14: 576.58516 | BZ14: 569.49267
B15: 100 ml | E15: 1335.7143 | F15: 1335.7321 | I15: 1335.75 | J15: 667.875 | K15: 667.875 | N15: 2003.625 | O15: 7346.5714 | P15: 2671.5 | Q15: 667.875 | R15: 667.875 | T15: 4007.25 | W15: 2 | X15: 2 | AA15: 2 | AB15: 1 | AC15: 1 | AF15: 3 | AG15: 11 | AH15: 4 | AI15: 1 | AJ15: 1 | AL15: 6 | AO15: 1 | AP15: 1 | AS15: 1 | AT15: 1 | AU15: 1 | AX15: 1 | AY15: 1 | AZ15: 1 | BA15: 1 | BB15: 1 | BD15: 1 | BE15: 11353.821 | BF15: 17 | BG15: 1 | BK15: 667.85714 | BL15: 667.86607 | BO15: 667.875 | BP15: 667.875 | BQ15: 667.875 | BT15: 667.875 | BU15: 667.87013 | BV15: 667.875 | BW15: 667.875 | BX15: 667.875 | BZ15: 667.875
A16: Consistent instock/Sales issue, price is fixed, no change in price ever in a cream squeeze packaging, still not in stock | B16: Durex Naturals Pure Intimate Lubricant Gel, 100ml | E16: 1335.7143 | F16: 1335.7321 | I16: 1335.75 | J16: 667.875 | K16: 667.875 | N16: 2003.625 | O16: 7346.5714 | P16: 2671.5 | Q16: 667.875 | R16: 667.875 | T16: 4007.25 | W16: 2 | X16: 2 | AA16: 2 | AB16: 1 | AC16: 1 | AF16: 3 | AG16: 11 | AH16: 4 | AI16: 1 | AJ16: 1 | AL16: 6 | AO16: 1 | AP16: 1 | AS16: 1 | AT16: 1 | AU16: 1 | AX16: 1 | AY16: 1 | AZ16: 1 | BA16: 1 | BB16: 1 | BD16: 1 | BE16: 11353.821 | BF16: 17 | BG16: 1 | BH16: 9 | BK16: 667.85714 | BL16: 667.86607 | BO16: 667.875 | BP16: 667.875 | BQ16: 667.875 | BT16: 667.875 | BU16: 667.87013 | BV16: 667.875 | BW16: 667.875 | BX16: 667.875 | BZ16: 667.875
A17: sales drop in Ramadan | B17: Grand Total | C17: 509198.17 | D17: 541319.17 | E17: 446448.93 | F17: 587650.54 | G17: 645248.62 | H17: 667614.3 | I17: 663708.68 | J17: 696632.02 | K17: 665455.35 | L17: 710364.15 | M17: 687870.07 | N17: 675122.32 | O17: 7496632.3 | P17: 697035.98 | Q17: 594443.85 | R17: 613511.18 | S17: 651976.2 | T17: 2556967.2 | U17: 1760 | V17: 1769 | W17: 1450 | X17: 1932 | Y17: 2168 | Z17: 2326 | AA17: 2325 | AB17: 2392 | AC17: 2165 | AD17: 2227 | AE17: 2358 | AF17: 2295 | AG17: 25167 | AH17: 2398 | AI17: 2064 | AJ17: 2127 | AK17: 2263 | AL17: 8852 | AM17: 6 | AN17: 6 | AO17: 7 | AP17: 7 | AQ17: 6 | AR17: 6 | AS17: 7 | AT17: 7 | AU17: 7 | AV17: 6 | AW17: 6 | AX17: 7 | AY17: 7 | AZ17: 7 | BA17: 7 | BB17: 7 | BC17: 6 | BD17: 7 | BE17: 10053600 | BF17: 34019 | BG17: 7 | BH17: 105 | BI17: 289.31714 | BJ17: 306.00293 | BK17: 307.89581 | BL17: 304.16695 | BM17: 297.6239 | BN17: 287.02248 | BO17: 285.4661 | BP17: 291.23412 | BQ17: 307.36968 | BR17: 318.97806 | BS17: 291.71759 | BT17: 294.17095 | BU17: 297.87549 | BV17: 290.67388 | BW17: 288.00574 | BX17: 288.43967 | BY17: 288.10261 | BZ17: 288.85757
A19: 200 ml has 3 variants- aloe, ylang ylang and guarana, guarana is not on talabat
A20: play has 5 variant in 50 ml- heat and stawberry not on talabat
A21: so intotal play has 8 variants- 5 on talabat
A22: aloevera sells more than ylang ylang in 200 ml
A23: huge difference in price of amazon vs talabat as of today- play almost 1.78x of amazon on talabat
A24: extra sensitive 100 ml on amazon, not on talabat
A25: amazon has multiple more variants which are not live on Talabat

Sheet Lubes Deep Dive
B1: Durex Lubes on Talabat: SKU deep dive
B2: All numbers are formulas on 'Lubes SKU level summary' unless marked. Revenue is in the same unit as the source data. JA = Jan-Apr. H2'25 = Jul-Dec 2025 monthly average.
B4: A. SKU scorecard: YoY growth vs. the H2-2025 run rate
B5: SKU | C5: Pack | D5: Rev JA'25 | E5: Rev JA'26 | F5: YoY rev % | G5: Units JA'25 | H5: Units JA'26 | I5: YoY units % | J5: ASP JA'25 | K5: ASP JA'26 | L5: ASP chg % | M5: H2'25 avg rev / mo | N5: Apr'26 rev | O5: Apr'26 vs H2'25 avg | P5: Share of lubes rev JA'26 | Q5: Read
B6: Play Cheeky Cherry | C6: 50 ml | D6: =SUM('Lubes SKU level summary'!C8:F8) -> 684899.92 | E6: =SUM('Lubes SKU level summary'!P8:S8) -> 810202.57 | F6: =IFERROR(E6/D6-1,0) -> 0.1829503 | G6: =SUM('Lubes SKU level summary'!U8:X8) -> 2524 | H6: =SUM('Lubes SKU level summary'!AH8:AK8) -> 3234 | I6: =IFERROR(H6/G6-1,0) -> 0.28129952 | J6: =IFERROR(D6/G6,0) -> 271.35496 | K6: =IFERROR(E6/H6,0) -> 250.52646 | L6: =IFERROR(K6/J6-1,0) -> -0.0767574 | M6: =SUM('Lubes SKU level summary'!I8:N8)/6 -> 209988.14 | N6: =N('Lubes SKU level summary'!S8) -> 220476.9 | O6: =IFERROR(N6/M6-1,0) -> 0.049949292 | P6: =IFERROR(E6/E$13,0) -> 0.31686076 | Q6: Hero SKU, about 1/3 of lubes. Growing and at its H2 level by April.
B7: Play Feel | C7: 50 ml | D7: =SUM('Lubes SKU level summary'!C9:F9) -> 455196.21 | E7: =SUM('Lubes SKU level summary'!P9:S9) -> 666276.38 | F7: =IFERROR(E7/D7-1,0) -> 0.46371248 | G7: =SUM('Lubes SKU level summary'!U9:X9) -> 1742 | H7: =SUM('Lubes SKU level summary'!AH9:AK9) -> 2715 | I7: =IFERROR(H7/G7-1,0) -> 0.55855339 | J7: =IFERROR(D7/G7,0) -> 261.30667 | K7: =IFERROR(E7/H7,0) -> 245.40566 | L7: =IFERROR(K7/J7-1,0) -> -0.060851881 | M7: =SUM('Lubes SKU level summary'!I9:N9)/6 -> 173569.71 | N7: =N('Lubes SKU level summary'!S9) -> 170192.33 | O7: =IFERROR(N7/M7-1,0) -> -0.019458405 | P7: =IFERROR(E7/E$13,0) -> 0.26057291 | Q7: Fastest grower (+56% units YoY). Holding its H2 level.
B8: Play Tingle | C8: 50 ml | D8: =SUM('Lubes SKU level summary'!C10:F10) -> 270715.4 | E8: =SUM('Lubes SKU level summary'!P10:S10) -> 297903.9 | F8: =IFERROR(E8/D8-1,0) -> 0.10043204 | G8: =SUM('Lubes SKU level summary'!U10:X10) -> 999 | H8: =SUM('Lubes SKU level summary'!AH10:AK10) -> 1187 | I8: =IFERROR(H8/G8-1,0) -> 0.18818819 | J8: =IFERROR(D8/G8,0) -> 270.98639 | K8: =IFERROR(E8/H8,0) -> 250.97211 | L8: =IFERROR(K8/J8-1,0) -> -0.073857112 | M8: =SUM('Lubes SKU level summary'!I10:N10)/6 -> 78534.845 | N8: =N('Lubes SKU level summary'!S10) -> 69610.725 | O8: =IFERROR(N8/M8-1,0) -> -0.11363262 | P8: =IFERROR(E8/E$13,0) -> 0.11650674 | Q8: Growing YoY but softer than the other Play SKUs. ~10% below its H2 level.
B9: Maxima Lubricant Gel | C9: 50 ml | D9: =SUM('Lubes SKU level summary'!C11:F11) -> 284497.5 | E9: =SUM('Lubes SKU level summary'!P11:S11) -> 265995 | F9: =IFERROR(E9/D9-1,0) -> -0.065035709 | G9: =SUM('Lubes SKU level summary'!U11:X11) -> 994 | H9: =SUM('Lubes SKU level summary'!AH11:AK11) -> 814 | I9: =IFERROR(H9/G9-1,0) -> -0.18108652 | J9: =IFERROR(D9/G9,0) -> 286.21479 | K9: =IFERROR(E9/H9,0) -> 326.77518 | L9: =IFERROR(K9/J9-1,0) -> 0.14171315 | M9: =SUM('Lubes SKU level summary'!I11:N11)/6 -> 77922.332 | N9: =N('Lubes SKU level summary'!S11) -> 68949.6 | O9: =IFERROR(N9/M9-1,0) -> -0.11514968 | P9: =IFERROR(E9/E$13,0) -> 0.10402754 | Q9: The only 50 ml SKU declining. ASP up 14% with no promo since Jan-26 (see B).
B10: Play Massage 2-in-1 Aloe Vera | C10: 200 ml | D10: =SUM('Lubes SKU level summary'!C13:F13) -> 226897.42 | E10: =SUM('Lubes SKU level summary'!P13:S13) -> 285354.53 | F10: =IFERROR(E10/D10-1,0) -> 0.2576367 | G10: =SUM('Lubes SKU level summary'!U13:X13) -> 382 | H10: =SUM('Lubes SKU level summary'!AH13:AK13) -> 497 | I10: =IFERROR(H10/G10-1,0) -> 0.30104712 | J10: =IFERROR(D10/G10,0) -> 593.97231 | K10: =IFERROR(E10/H10,0) -> 574.15397 | L10: =IFERROR(K10/J10-1,0) -> -0.033365753 | M10: =SUM('Lubes SKU level summary'!I13:N13)/6 -> 79854.288 | N10: =N('Lubes SKU level summary'!S13) -> 67394.475 | O10: =IFERROR(N10/M10-1,0) -> -0.15603186 | P10: =IFERROR(E10/E$13,0) -> 0.11159882 | Q10: Out-sells Ylang but has the biggest fall vs H2 of any SKU.
B11: Play Massage 2-in-1 Ylang Ylang | C11: 200 ml | D11: =SUM('Lubes SKU level summary'!C14:F14) -> 159738.92 | E11: =SUM('Lubes SKU level summary'!P14:S14) -> 227227.58 | F11: =IFERROR(E11/D11-1,0) -> 0.42249352 | G11: =SUM('Lubes SKU level summary'!U14:X14) -> 266 | H11: =SUM('Lubes SKU level summary'!AH14:AK14) -> 399 | I11: =IFERROR(H11/G11-1,0) -> 0.5 | J11: =IFERROR(D11/G11,0) -> 600.52225 | K11: =IFERROR(E11/H11,0) -> 569.49267 | L11: =IFERROR(K11/J11-1,0) -> -0.051670989 | M11: =SUM('Lubes SKU level summary'!I14:N14)/6 -> 62543.591 | N11: =N('Lubes SKU level summary'!S14) -> 55352.175 | O11: =IFERROR(N11/M11-1,0) -> -0.11498246 | P11: =IFERROR(E11/E$13,0) -> 0.08886605 | Q11: YoY flattered by a weak Jan-25 base (only 14 stores ranged it).
B12: Naturals Pure Intimate | C12: 100 ml | D12: =SUM('Lubes SKU level summary'!C16:F16) -> 2671.4464 | E12: =SUM('Lubes SKU level summary'!P16:S16) -> 4007.25 | F12: =IFERROR(E12/D12-1,0) -> 0.50003008 | G12: =SUM('Lubes SKU level summary'!U16:X16) -> 4 | H12: =SUM('Lubes SKU level summary'!AH16:AK16) -> 6 | I12: =IFERROR(H12/G12-1,0) -> 0.5 | J12: =IFERROR(D12/G12,0) -> 667.86161 | K12: =IFERROR(E12/H12,0) -> 667.875 | L12: =IFERROR(K12/J12-1,0) -> 2.0053342e-05 | M12: =SUM('Lubes SKU level summary'!I16:N16)/6 -> 779.1875 | N12: =N('Lubes SKU level summary'!S16) -> 0 | O12: =IFERROR(N12/M12-1,0) -> -1 | P12: =IFERROR(E12/E$13,0) -> 0.0015671887 | Q12: 17 units in 16 months, 1 store at a time. Effectively not ranged.
B13: Total lubes | D13: =SUM(D6:D12) -> 2084616.8 | E13: =SUM(E6:E12) -> 2556967.2 | F13: =IFERROR(E13/D13-1,0) -> 0.22658859 | G13: =SUM(G6:G12) -> 6911 | H13: =SUM(H6:H12) -> 8852 | I13: =IFERROR(H13/G13-1,0) -> 0.28085661 | J13: =IFERROR(D13/G13,0) -> 301.63751 | K13: =IFERROR(E13/H13,0) -> 288.85757 | L13: =IFERROR(K13/J13-1,0) -> -0.042368534 | M13: =SUM(M6:M12) -> 683192.1 | N13: =SUM(N6:N12) -> 651976.2 | O13: =IFERROR(N13/M13-1,0) -> -0.045691248 | P13: =IFERROR(E13/E13,0) -> 1 | Q13: Lubes are growing YoY; the gap is against the H2-25 run rate, not last year.
B14: ="Check vs pivot Grand Total JA'26: "&TEXT('Lubes SKU level summary'!T17-E13,"#,##0")&" difference" -> Check vs pivot Grand Total JA'26: 0 difference
B16: B. Maxima 50 ml: price premium vs Play 50 ml, and its share of 50 ml units
B17: Metric | C17: Jan-25 | D17: Feb-25 | E17: Mar-25 | F17: Apr-25 | G17: May-25 | H17: Jun-25 | I17: Jul-25 | J17: Aug-25 | K17: Sep-25 | L17: Oct-25 | M17: Nov-25 | N17: Dec-25 | O17: Jan-26 | P17: Feb-26 | Q17: Mar-26 | R17: Apr-26
B18: Maxima ASP | C18: =IFERROR('Lubes SKU level summary'!C11/'Lubes SKU level summary'!U11,0) -> 289.59109 | D18: =IFERROR('Lubes SKU level summary'!D11/'Lubes SKU level summary'!V11,0) -> 286.2499 | E18: =IFERROR('Lubes SKU level summary'!E11/'Lubes SKU level summary'!W11,0) -> 286.99517 | F18: =IFERROR('Lubes SKU level summary'!F11/'Lubes SKU level summary'!X11,0) -> 282.51319 | G18: =IFERROR('Lubes SKU level summary'!G11/'Lubes SKU level summary'!Y11,0) -> 286.27948 | H18: =IFERROR('Lubes SKU level summary'!H11/'Lubes SKU level summary'!Z11,0) -> 278.43943 | I18: =IFERROR('Lubes SKU level summary'!I11/'Lubes SKU level summary'!AA11,0) -> 285.4838 | J18: =IFERROR('Lubes SKU level summary'!J11/'Lubes SKU level summary'!AB11,0) -> 286.52213 | ... N18: =IFERROR('Lubes SKU level summary'!N11/'Lubes SKU level summary'!AF11,0) -> 313.35846 | O18: =IFERROR('Lubes SKU level summary'!P11/'Lubes SKU level summary'!AH11,0) -> 326.775 | P18: =IFERROR('Lubes SKU level summary'!Q11/'Lubes SKU level summary'!AI11,0) -> 326.77543 | Q18: =IFERROR('Lubes SKU level summary'!R11/'Lubes SKU level summary'!AJ11,0) -> 326.775 | R18: =IFERROR('Lubes SKU level summary'!S11/'Lubes SKU level summary'!AK11,0) -> 326.77536
B19: Play 50 ml blended ASP | C19: =IFERROR(SUM('Lubes SKU level summary'!C8:C10)/SUM('Lubes SKU level summary'!U8:U10),0) -> 262.63223 | D19: =IFERROR(SUM('Lubes SKU level summary'!D8:D10)/SUM('Lubes SKU level summary'!V8:V10),0) -> 272.1297 | E19: =IFERROR(SUM('Lubes SKU level summary'!E8:E10)/SUM('Lubes SKU level summary'!W8:W10),0) -> 272.17545 | F19: =IFERROR(SUM('Lubes SKU level summary'!F8:F10)/SUM('Lubes SKU level summary'!X8:X10),0) -> 265.90458 | G19: =IFERROR(SUM('Lubes SKU level summary'!G8:G10)/SUM('Lubes SKU level summary'!Y8:Y10),0) -> 261.25443 | H19: =IFERROR(SUM('Lubes SKU level summary'!H8:H10)/SUM('Lubes SKU level summary'!Z8:Z10),0) -> 248.65049 | I19: =IFERROR(SUM('Lubes SKU level summary'!I8:I10)/SUM('Lubes SKU level summary'!AA8:AA10),0) -> 251.5593 | J19: =IFERROR(SUM('Lubes SKU level summary'!J8:J10)/SUM('Lubes SKU level summary'!AB8:AB10),0) -> 252.31221 | ... N19: =IFERROR(SUM('Lubes SKU level summary'!N8:N10)/SUM('Lubes SKU level summary'!AF8:AF10),0) -> 249.07198 | O19: =IFERROR(SUM('Lubes SKU level summary'!P8:P10)/SUM('Lubes SKU level summary'!AH8:AH10),0) -> 249.90987 | P19: =IFERROR(SUM('Lubes SKU level summary'!Q8:Q10)/SUM('Lubes SKU level summary'!AI8:AI10),0) -> 246.76803 | Q19: =IFERROR(SUM('Lubes SKU level summary'!R8:R10)/SUM('Lubes SKU level summary'!AJ8:AJ10),0) -> 247.31497 | R19: =IFERROR(SUM('Lubes SKU level summary'!S8:S10)/SUM('Lubes SKU level summary'!AK8:AK10),0) -> 250.28817
B20: Maxima premium vs Play | C20: =IFERROR(C18/C19-1,0) -> 0.10264871 | D20: =IFERROR(D18/D19-1,0) -> 0.051887741 | E20: =IFERROR(E18/E19-1,0) -> 0.054449144 | F20: =IFERROR(F18/F19-1,0) -> 0.062460808 | G20: =IFERROR(G18/G19-1,0) -> 0.095788031 | H20: =IFERROR(H18/H19-1,0) -> 0.11980245 | I20: =IFERROR(I18/I19-1,0) -> 0.13485685 | J20: =IFERROR(J18/J19-1,0) -> 0.13558566 | ... R20: =IFERROR(R18/R19-1,0) -> 0.30559647
B21: Maxima share of 50 ml units | C21: =IFERROR('Lubes SKU level summary'!U11/'Lubes SKU level summary'!U7,0) -> 0.159438 | D21: =IFERROR('Lubes SKU level summary'!V11/'Lubes SKU level summary'!V7,0) -> 0.1514393 | E21: =IFERROR('Lubes SKU level summary'!W11/'Lubes SKU level summary'!W7,0) -> 0.15862069 | F21: =IFERROR('Lubes SKU level summary'!X11/'Lubes SKU level summary'!X7,0) -> 0.16521233 | G21: =IFERROR('Lubes SKU level summary'!Y11/'Lubes SKU level summary'!Y7,0) -> 0.16232772 | H21: =IFERROR('Lubes SKU level summary'!Z11/'Lubes SKU level summary'!Z7,0) -> 0.16802688 | I21: =IFERROR('Lubes SKU level summary'!AA11/'Lubes SKU level summary'!AA7,0) -> 0.15326395 | J21: =IFERROR('Lubes SKU level summary'!AB11/'Lubes SKU level summary'!AB7,0) -> 0.14285714 | ... N21: =IFERROR('Lubes SKU level summary'!AF11/'Lubes SKU level summary'!AF7,0) -> 0.097014925 | O21: =IFERROR('Lubes SKU level summary'!AH11/'Lubes SKU level summary'!AH7,0) -> 0.10641264 | P21: =IFERROR('Lubes SKU level summary'!AI11/'Lubes SKU level summary'!AI7,0) -> 0.093766938 | Q21: =IFERROR('Lubes SKU level summary'!AJ11/'Lubes SKU level summary'!AJ7,0) -> 0.1056227 | R21: =IFERROR('Lubes SKU level summary'!AK11/'Lubes SKU level summary'!AK7,0) -> 0.10292683
B22: Play 50 ml units | C22: =SUM('Lubes SKU level summary'!U8:U10) -> 1376 | D22: =SUM('Lubes SKU level summary'!V8:V10) -> 1356 | E22: =SUM('Lubes SKU level summary'!W8:W10) -> 1098 | F22: =SUM('Lubes SKU level summary'!X8:X10) -> 1435 | G22: =SUM('Lubes SKU level summary'!Y8:Y10) -> 1641 | H22: =SUM('Lubes SKU level summary'!Z8:Z10) -> 1733 | I22: =SUM('Lubes SKU level summary'!AA8:AA10) -> 1790 | J22: =SUM('Lubes SKU level summary'!AB8:AB10) -> 1830 | ... N22: =SUM('Lubes SKU level summary'!AF8:AF10) -> 1815 | O22: =SUM('Lubes SKU level summary'!AH8:AH10) -> 1923 | P22: =SUM('Lubes SKU level summary'!AI8:AI10) -> 1672 | Q22: =SUM('Lubes SKU level summary'!AJ8:AJ10) -> 1702 | R22: =SUM('Lubes SKU level summary'!AK8:AK10) -> 1839
B23: Maxima units | C23: =N('Lubes SKU level summary'!U11) -> 261 | D23: =N('Lubes SKU level summary'!V11) -> 242 | E23: =N('Lubes SKU level summary'!W11) -> 207 | F23: =N('Lubes SKU level summary'!X11) -> 284 | G23: =N('Lubes SKU level summary'!Y11) -> 318 | H23: =N('Lubes SKU level summary'!Z11) -> 350 | I23: =N('Lubes SKU level summary'!AA11) -> 324 | J23: =N('Lubes SKU level summary'!AB11) -> 305 | ... N23: =N('Lubes SKU level summary'!AF11) -> 195 | O23: =N('Lubes SKU level summary'!AH11) -> 229 | P23: =N('Lubes SKU level summary'!AI11) -> 173 | Q23: =N('Lubes SKU level summary'!AJ11) -> 201 | R23: =N('Lubes SKU level summary'!AK11) -> 211
B24: Feb-25 order-level data shows 326.8 was already Maxima's full-price point (9 units); 285.3 was the regular promoted price (225 units). Since Jan-26 (and mostly in Dec-25) every unit sells at 326.8, so the promo looks switched off. Meanwhile Play 50 ml went down from ~272 to ~250. The premium widened from ~5% to ~30% and Maxima's share of 50 ml units fell from ~16% to ~10%.
B26: C. Ramadan effect on lubes units (your remark: "sales drop in Ramadan")
B27: Year | C27: Pre-Ramadan base | D27: Base definition | E27: Ramadan month(s) | F27: Ramadan units | G27: Dip vs base | H27: Post-Ramadan (Apr) | I27: Apr vs base
B28: 2025 | C28: =AVERAGE('Lubes SKU level summary'!U17:V17) -> 1764.5 | D28: Jan-Feb avg | E28: Mar-25 (Ramadan ~1-30 Mar) | F28: ='Lubes SKU level summary'!W17 -> 1450 | G28: =F28/C28-1 -> -0.17823746 | H28: ='Lubes SKU level summary'!X17 -> 1932 | I28: =H28/C28-1 -> 0.094927742
B29: 2026 | C29: ='Lubes SKU level summary'!AH17 -> 2398 | D29: Jan | E29: Feb-Mar 26 avg (Ramadan ~18 Feb-19 Mar) | F29: =AVERAGE('Lubes SKU level summary'!AI17:AJ17) -> 2095.5 | G29: =F29/C29-1 -> -0.12614679 | H29: ='Lubes SKU level summary'!AK17 -> 2263 | I29: =H29/C29-1 -> -0.056296914
B30: Confirmed: Ramadan takes 13-18% off lubes units, and April has not fully recovered to the Jan-26 base yet. Ramadan 2027 is expected around 8 Feb - 9 Mar, so plan the pre-load and Eid visibility now.
B32: D. Store reach and velocity (Raw data: Location is only filled for Jan/Apr/May/Aug 2025)
B33: SKU | C33: Stores Jan-25 | D33: Stores Apr-25 | E33: Stores May-25 | F33: Stores Aug-25 | G33: Units/store Jan-25 | H33: Units/store Apr-25 | I33: Units/store May-25 | J33: Units/store Aug-25 | K33: Reach Aug-25 (of 40 active)
B34: Play Cheeky Cherry | C34: 41 | D34: 35 | E34: 36 | F34: 39 | G34: =IFERROR('Lubes SKU level summary'!U8/C34,0) -> 14.658537 | H34: =IFERROR('Lubes SKU level summary'!X8/D34,0) -> 19.428571 | I34: =IFERROR('Lubes SKU level summary'!Y8/E34,0) -> 20.027778 | J34: =IFERROR('Lubes SKU level summary'!AB8/F34,0) -> 22.410256 | K34: =IFERROR(F34/F$41,0) -> 0.975
B35: Play Feel | C35: 43 | D35: 37 | E35: 37 | F35: 39 | G35: =IFERROR('Lubes SKU level summary'!U9/C35,0) -> 12.372093 | H35: =IFERROR('Lubes SKU level summary'!X9/D35,0) -> 13 | I35: =IFERROR('Lubes SKU level summary'!Y9/E35,0) -> 16.297297 | J35: =IFERROR('Lubes SKU level summary'!AB9/F35,0) -> 16 | K35: =IFERROR(F35/F$41,0) -> 0.975
B36: Play Tingle | C36: 39 | D36: 36 | E36: 36 | F36: 39 | G36: =IFERROR('Lubes SKU level summary'!U10/C36,0) -> 6.2307692 | H36: =IFERROR('Lubes SKU level summary'!X10/D36,0) -> 7.6111111 | I36: =IFERROR('Lubes SKU level summary'!Y10/E36,0) -> 8.8055556 | J36: =IFERROR('Lubes SKU level summary'!AB10/F36,0) -> 8.5128205 | K36: =IFERROR(F36/F$41,0) -> 0.975
B37: Maxima Lubricant Gel | C37: 38 | D37: 35 | E37: 36 | F37: 37 | G37: =IFERROR('Lubes SKU level summary'!U11/C37,0) -> 6.8684211 | H37: =IFERROR('Lubes SKU level summary'!X11/D37,0) -> 8.1142857 | I37: =IFERROR('Lubes SKU level summary'!Y11/E37,0) -> 8.8333333 | J37: =IFERROR('Lubes SKU level summary'!AB11/F37,0) -> 8.2432432 | K37: =IFERROR(F37/F$41,0) -> 0.925
B38: Play Massage 2-in-1 Aloe Vera | C38: 34 | D38: 34 | E38: 31 | F38: 36 | G38: =IFERROR('Lubes SKU level summary'!U13/C38,0) -> 2.8529412 | H38: =IFERROR('Lubes SKU level summary'!X13/D38,0) -> 3.4411765 | I38: =IFERROR('Lubes SKU level summary'!Y13/E38,0) -> 3.6451613 | J38: =IFERROR('Lubes SKU level summary'!AB13/F38,0) -> 3.8055556 | K38: =IFERROR(F38/F$41,0) -> 0.9
B39: Play Massage 2-in-1 Ylang Ylang | C39: 14 | D39: 33 | E39: 31 | F39: 37 | G39: =IFERROR('Lubes SKU level summary'!U14/C39,0) -> 1.8571429 | H39: =IFERROR('Lubes SKU level summary'!X14/D39,0) -> 2.8484848 | I39: =IFERROR('Lubes SKU level summary'!Y14/E39,0) -> 3.0967742 | J39: =IFERROR('Lubes SKU level summary'!AB14/F39,0) -> 3.2162162 | K39: =IFERROR(F39/F$41,0) -> 0.925
B40: Naturals Pure Intimate | C40: 0 | D40: 1 | E40: 0 | F40: 1 | G40: =IFERROR('Lubes SKU level summary'!U16/C40,0) -> 0 | H40: =IFERROR('Lubes SKU level summary'!X16/D40,0) -> 2 | I40: =IFERROR('Lubes SKU level summary'!Y16/E40,0) -> 0 | J40: =IFERROR('Lubes SKU level summary'!AB16/F40,0) -> 1 | K40: =IFERROR(F40/F$41,0) -> 0.025
B41: Active Durex stores (any SKU) | C41: 62 | D41: 37 | E41: 37 | F41: 40
B42: Blue = hardcoded from 'Raw data' (distinct Location with >=1 unit sold). Jan-25 includes 26 'Talabat Mart - Wellness' stores that sold only 73 Durex units in total and drop out after January. In 2025 the core SKUs sold in 90-100% of stores, so ranging was not the issue then. There is no store-level data for 2026, so ask Talabat for 2026 in-stock % by dark store before calling the decline a demand problem.
B44: E. Your remarks, checked against the data
B45: Your remark (col A, Lubes SKU level summary) | C45: What the data says | D45: Verdict | E45: So what / action
...
